Workbook

Sheet Test Cases
A1: ParaBank Sign-Up & Login Automation - Test Case Suite
A2: Application: https://parabank.parasoft.com/parabank/ | Framework: Playwright + TypeScript, BDD + POM | 33 automated test cases | Latest run: 24-May-2026 - PASS (33 / 33)
A3: TC ID | B3: Smoke | C3: Reg. | D3: E2E | E3: Auto | F3: Test Type | G3: Module | H3: Functional Area | I3: Test Case | J3: Pre-condition | K3: Test Steps | L3: Test Data | M3: Expected Result | N3: Priority | O3: Status | P3: Remarks
A4: Functional Tests
A5: TC-001 | B5: Y | C5: Y | D5: - | E5: Y | F5: Functional | G5: Account Registration | H5: Form Submission | I5: Register a new customer with valid details | J5: ParaBank is reachable; no customer is signed in. | K5: 1. Open the registration page (/register.htm). 2. Complete every mandatory field with valid data. 3. Enter a unique username and matching passwords. 4. Click 'Register'. | L5: Valid customer data; unique username; Password = Confirm Password. | M5: Account is created. Message "Your account was created successfully. You are now logged in." is shown and the customer is auto-signed-in. | N5: P1 - High | O5: Pass
A6: TC-002 | B6: - | C6: Y | D6: - | E6: Y | F6: Functional | G6: Account Registration | H6: Field Validation | I6: Registration is rejected when mandatory fields are empty | J6: ParaBank is reachable. | K6: 1. Open /register.htm. 2. Leave every field blank. 3. Click 'Register'. | L6: None (all fields empty). | M6: Registration is blocked; field-level errors are shown ("First name is required.", etc.). | N6: P2 - Medium | O6: Pass
A7: TC-003 | B7: - | C7: Y | D7: - | E7: Y | F7: Functional | G7: Account Registration | H7: Duplicate Detection | I7: Registration is rejected for an already registered username | J7: A customer account has already been registered. | K7: 1. Register a customer and note the username. 2. Log out. 3. Open /register.htm. 4. Register again with the same username. 5. Click 'Register'. | L7: An already-registered username. | M7: Registration is rejected with the error "This username already exists.". | N7: P2 - Medium | O7: Pass
A8: TC-004 | B8: Y | C8: Y | D8: Y | E8: Y | F8: Functional | G8: Account Login | H8: Authentication | I8: Sign in with a new account and view the post-login balance | J8: A registered account exists; no customer is signed in. | K8: 1. Register a customer and log out. 2. Enter the username and password on the home page. 3. Click 'Log In'. 4. Read the balance on the Accounts Overview page. | L8: Valid credentials of the new account. | M8: Login succeeds; Accounts Overview is shown; the balance is displayed in currency format (e.g. $515.50) and logged to the console and balance.log. | N8: P1 - High | O8: Pass
A9: TC-005 | B9: - | C9: Y | D9: - | E9: Y | F9: Functional | G9: Account Login | H9: Authentication | I9: Sign in is rejected with invalid credentials | J9: On the home page; no customer is signed in. | K9: 1. Open /index.htm. 2. Enter a non-existent username and a wrong password. 3. Click 'Log In'. | L9: Username: no_such_user_2026 / Password: WrongPassword!1. | M9: Login fails with the error "The username and password could not be verified.". | N9: P2 - Medium | O9: Pass
A10: TC-006 | B10: - | C10: Y | D10: Y | E10: Y | F10: Functional | G10: Account Login | H10: Session Management | I10: Log out ends the session and returns to the login page | J10: A registered account exists. | K10: 1. Register a customer and log out. 2. Sign in with the credentials. 3. Click 'Log Out'. | L10: Valid credentials. | M10: The session ends and the Customer Login page is displayed. | N10: P2 - Medium | O10: Pass
A11: Boundary & Validation Tests
A12: TC-007 | B12: - | C12: Y | D12: - | E12: Y | F12: Boundary | G12: Account Registration | H12: Password Rules | I12: Registration is rejected when the password confirmation does not match | J12: On the registration page. | K12: 1. Open /register.htm. 2. Complete all valid fields. 3. Enter a Password and a different Confirm Password. 4. Click 'Register'. | L12: Password != Confirm Password. | M12: Registration is rejected with the error "Passwords did not match.". | N12: P2 - Medium | O12: Pass
A13: TC-008 | B13: - | C13: Y | D13: - | E13: Y | F13: Boundary | G13: Account Registration | H13: Mandatory Fields | I13: Registration is rejected when only some mandatory fields are completed | J13: On the registration page. | K13: 1. Open /register.htm. 2. Complete only First Name and Last Name. 3. Click 'Register'. | L13: Partial form - name fields only. | M13: Registration is rejected; validation errors are shown for the remaining mandatory fields (Address, City, ...). | N13: P2 - Medium | O13: Pass
A14: TC-009 | B14: - | C14: Y | D14: - | E14: Y | F14: Boundary | G14: Account Registration | H14: Input Boundaries | I14: Registration succeeds with minimum-length field values | J14: On the registration page. | K14: 1. Open /register.htm. 2. Fill each field with a single-character value. 3. Click 'Register'. | L14: 1-character field values; unique username. | M14: The lower input boundary is accepted and the account is created successfully. | N14: P3 - Low | O14: Pass
A15: TC-010 | B15: - | C15: Y | D15: - | E15: Y | F15: Boundary | G15: Account Registration | H15: Input Boundaries | I15: Registration succeeds with maximum-length field values | J15: On the registration page. | K15: 1. Open /register.htm. 2. Fill each field with long (24-40 character) values. 3. Click 'Register'. | L15: Long field values; unique username. | M15: The upper input boundary is accepted and the account is created successfully. | N15: P3 - Low | O15: Pass
A16: TC-011 | B16: - | C16: Y | D16: - | E16: Y | F16: Boundary | G16: Account Registration | H16: Input Boundaries | I16: Registration succeeds with special-character field values | J16: On the registration page. | K16: 1. Open /register.htm. 2. Fill name/address fields with hyphen and apostrophe characters. 3. Click 'Register'. | L16: Names such as Mary-Jane, O'Brien-D'Souza. | M16: Special characters are accepted and the account is created successfully. | N16: P3 - Low | O16: Pass
A17: TC-012 | B17: - | C17: Y | D17: - | E17: Y | F17: Boundary | G17: Account Login | H17: Credential Validation | I17: Login is rejected when the username is empty | J17: On the home page; no customer is signed in. | K17: 1. Open /index.htm. 2. Leave the username empty; enter a password. 3. Click 'Log In'. | L17: Empty username. | M17: Login is rejected and an error message is displayed ("Please enter a username and password."). | N17: P2 - Medium | O17: Pass
A18: TC-013 | B18: - | C18: Y | D18: - | E18: Y | F18: Boundary | G18: Account Login | H18: Credential Validation | I18: Login is rejected when the password is empty | J18: On the home page; no customer is signed in. | K18: 1. Open /index.htm. 2. Enter a username; leave the password empty. 3. Click 'Log In'. | L18: Empty password. | M18: Login is rejected and an error message is displayed ("Please enter a username and password."). | N18: P2 - Medium | O18: Pass
A19: TC-014 | B19: - | C19: Y | D19: - | E19: Y | F19: Boundary | G19: Account Login | H19: Credential Validation | I19: Login is rejected when both username and password are empty | J19: On the home page; no customer is signed in. | K19: 1. Open /index.htm. 2. Leave both fields empty. 3. Click 'Log In'. | L19: Empty username and password. | M19: Login is rejected and the error "Please enter a username and password." is displayed. | N19: P2 - Medium | O19: Pass
A20: Security Tests
A21: TC-015 | B21: - | C21: Y | D21: - | E21: Y | F21: Security | G21: Account Registration | H21: Input Masking | I21: Registration Password field masks the entered characters | J21: On the registration page. | K21: 1. Open /register.htm. 2. Type into the Password field. 3. Inspect the field input type. | L21: Any password value. | M21: The Password field is of type 'password'; typed characters are not shown in clear text. | N21: P2 - Medium | O21: Pass
A22: TC-016 | B22: - | C22: Y | D22: - | E22: Y | F22: Security | G22: Account Registration | H22: Input Masking | I22: Registration Confirm Password field masks the entered characters | J22: On the registration page. | K22: 1. Open /register.htm. 2. Type into the Confirm Password field. 3. Inspect the field input type. | L22: Any password value. | M22: The Confirm Password field is of type 'password'; typed characters are masked. | N22: P2 - Medium | O22: Pass
A23: TC-017 | B23: - | C23: Y | D23: - | E23: Y | F23: Security | G23: Account Login | H23: Input Masking | I23: Login Password field masks the entered characters | J23: On the home page. | K23: 1. Open /index.htm. 2. Type into the login Password field. 3. Inspect the field input type. | L23: Any password value. | M23: The login Password field is of type 'password'; typed characters are masked. | N23: P2 - Medium | O23: Pass
A24: TC-018 | B24: Y | C24: Y | D24: - | E24: Y | F24: Security | G24: Account Login | H24: Injection Defence | I24: SQL injection in the login form does not bypass authentication | J24: On the home page; no customer is signed in. | K24: 1. Open /index.htm. 2. Enter a SQL injection payload as username and password. 3. Click 'Log In'. | L24: Payload: ' OR '1'='1 | M24: Authentication is not bypassed; the customer is not signed in and the Accounts Overview is not reached (request rejected by the application / WAF). | N24: P1 - High | O24: Pass
A25: TC-019 | B25: - | C25: Y | D25: - | E25: Y | F25: Security | G25: Account Registration | H25: Injection Defence | I25: HTML / script injection in the first name field is neutralised | J25: On the registration page. | K25: 1. Open /register.htm. 2. Register with an HTML payload (e.g. <b>...</b>) as the First Name. 3. View the post-registration page. | L25: First Name: <b>QA-XSS</b> | M25: Expected: the injected markup is escaped and never rendered as live page content. | N25: P1 - High | O25: Observation | P25: KNOWN DEFECT: ParaBank renders the first name unescaped, confirming a stored XSS / HTML-injection exposure. The scenario is tagged @fail (expected failure) so the regression suite stays green while flagging the issue.
A26: TC-020 | B26: Y | C26: Y | D26: - | E26: Y | F26: Security | G26: Cross-cutting | H26: Transport Security | I26: The application is served over a secure HTTPS connection | J26: ParaBank is reachable. | K26: 1. Open the ParaBank home page. 2. Inspect the page URL scheme. | L26: None. | M26: The page is served over https:// - traffic is encrypted in transit. | N26: P2 - Medium | O26: Pass
A27: TC-021 | B27: - | C27: Y | D27: Y | E27: Y | F27: Security | G27: Account Login | H27: Session Hardening | I27: The session cookie is protected with the HttpOnly flag | J27: A registered account exists. | K27: 1. Register a customer and sign in. 2. Inspect the JSESSIONID session cookie. | L27: Valid credentials. | M27: A JSESSIONID cookie is set and flagged HttpOnly, so it cannot be read by client-side scripts. | N27: P1 - High | O27: Pass
A28: TC-022 | B28: - | C28: Y | D28: Y | E28: Y | F28: Security | G28: Account Login | H28: Enumeration Defence | I28: Login errors do not reveal whether a username exists | J28: A registered account exists. | K28: 1. Sign in with a valid username and a wrong password. 2. Sign in with an unknown username and password. 3. Compare the two error messages. | L28: Valid username + wrong password; unknown username + password. | M28: Both attempts return the identical generic error message - the response does not disclose whether a username exists. | N28: P2 - Medium | O28: Pass
A29: TC-023 | B29: - | C29: Y | D29: - | E29: Y | F29: Security | G29: Account Login | H29: Brute-force Resilience | I29: Repeated failed logins are consistently rejected | J29: On the home page; no customer is signed in. | K29: 1. Open /index.htm. 2. Submit 5 consecutive invalid login attempts. | L29: 5 distinct invalid credential pairs. | M29: Every attempt is rejected; repetition does not bypass authentication. | N29: P2 - Medium | O29: Pass
A30: Access Control Tests
A31: TC-024 | B31: - | C31: Y | D31: - | E31: Y | F31: Access Control | G31: Session & Access | H31: Unauthorised Access | I31: Accounts Overview is not accessible while logged out | J31: No customer is signed in. | K31: 1. Ensure no customer is signed in. 2. Open /overview.htm directly. | L31: Direct URL: /overview.htm. | M31: Access is denied; the ParaBank error page is shown, no account data is exposed and the visitor is not signed in. | N31: P1 - High | O31: Pass
A32: TC-025 | B32: - | C32: Y | D32: - | E32: Y | F32: Access Control | G32: Session & Access | H32: Unauthorised Access | I32: Transfer Funds page is not accessible while logged out | J32: No customer is signed in. | K32: 1. Ensure no customer is signed in. 2. Open /transfer.htm directly. | L32: Direct URL: /transfer.htm. | M32: Access is denied; the ParaBank error page is shown and no transfer functionality is exposed. | N32: P2 - Medium | O32: Pass
A33: TC-026 | B33: - | C33: Y | D33: - | E33: Y | F33: Access Control | G33: Session & Access | H33: Unauthorised Access | I33: Update Contact Info page is not accessible while logged out | J33: No customer is signed in. | K33: 1. Ensure no customer is signed in. 2. Open /updateprofile.htm directly. | L33: Direct URL: /updateprofile.htm. | M33: Access is denied; the ParaBank error page is shown and no profile data is exposed. | N33: P2 - Medium | O33: Pass
A34: TC-027 | B34: - | C34: Y | D34: Y | E34: Y | F34: Access Control | G34: Session & Access | H34: Session Invalidation | I34: Protected pages are not accessible after logging out | J34: A registered account exists. | K34: 1. Register a customer and sign in. 2. Log out. 3. Open /overview.htm directly. | L34: Direct URL after logout. | M34: Access is denied after logout - the previous session can no longer reach protected pages. | N34: P1 - High | O34: Pass
A35: TC-028 | B35: - | C35: Y | D35: Y | E35: Y | F35: Access Control | G35: Session & Access | H35: Session Persistence | I35: An authenticated session persists across page navigation | J35: A registered account exists. | K35: 1. Register a customer and sign in. 2. Navigate across multiple authenticated pages. | L35: Valid credentials. | M35: The customer remains signed in throughout the navigation - the session is stable. | N35: P2 - Medium | O35: Pass
A36: Performance Tests
A37: TC-029 | B37: - | C37: Y | D37: - | E37: Y | F37: Performance | G37: Account Login | H37: Page Load | I37: The home page loads within the performance budget | J37: ParaBank is reachable. | K37: 1. Open the ParaBank home page and measure the load time. | L37: Budget: 15,000 ms. | M37: The measured load time is within budget; the value is logged to performance.log. | N37: P3 - Low | O37: Pass
A38: TC-030 | B38: - | C38: Y | D38: - | E38: Y | F38: Performance | G38: Account Registration | H38: Page Load | I38: The registration page loads within the performance budget | J38: ParaBank is reachable. | K38: 1. Open the registration page and measure the load time. | L38: Budget: 15,000 ms. | M38: The measured load time is within budget; the value is logged to performance.log. | N38: P3 - Low | O38: Pass
A39: TC-031 | B39: - | C39: Y | D39: Y | E39: Y | F39: Performance | G39: Account Registration | H39: Response Time | I39: Account registration completes within the performance budget | J39: On the registration page. | K39: 1. Submit the registration form and measure the response time. | L39: Budget: 30,000 ms (JPA insert). | M39: The registration response time is within budget; the value is logged to performance.log. | N39: P3 - Low | O39: Pass
A40: TC-032 | B40: - | C40: Y | D40: Y | E40: Y | F40: Performance | G40: Account Login | H40: Response Time | I40: Login completes within the performance budget | J40: A registered account exists. | K40: 1. Submit the login form and measure the response time until Accounts Overview is shown. | L40: Budget: 30,000 ms (JPA read + auth). | M40: The login response time is within budget; the value is logged to performance.log. | N40: P3 - Low | O40: Pass
...

Sheet Summary Report
A1: Summary Report - ParaBank Automation Test Suite
A3: Coverage by Test Type
A4: Test Type | B4: Total | C4: Automated | D4: Manual | E4: Coverage
A5: Functional | B5: =COUNTIF('Test Cases'!F5:F41,"Functional") -> 6 | C5: =COUNTIF('Test Cases'!F5:F41,"Functional") -> 6 | D5: 0 | E5: 100%
A6: Boundary | B6: =COUNTIF('Test Cases'!F5:F41,"Boundary") -> 8 | C6: =COUNTIF('Test Cases'!F5:F41,"Boundary") -> 8 | D6: 0 | E6: 100%
A7: Security | B7: =COUNTIF('Test Cases'!F5:F41,"Security") -> 9 | C7: =COUNTIF('Test Cases'!F5:F41,"Security") -> 9 | D7: 0 | E7: 100%
A8: Access Control | B8: =COUNTIF('Test Cases'!F5:F41,"Access Control") -> 5 | C8: =COUNTIF('Test Cases'!F5:F41,"Access Control") -> 5 | D8: 0 | E8: 100%
A9: Performance | B9: =COUNTIF('Test Cases'!F5:F41,"Performance") -> 5 | C9: =COUNTIF('Test Cases'!F5:F41,"Performance") -> 5 | D9: 0 | E9: 100%
A10: TOTAL | B10: =SUM(B5:B9) -> 33 | C10: =SUM(C5:C9) -> 33 | D10: =SUM(D5:D9) -> 0 | E10: 100%
A12: Coverage by Priority
A13: Priority | B13: Count | C13: Share
A14: P1 - High | B14: =COUNTIF('Test Cases'!N5:N41,"P1 - High") -> 7 | C14: =TEXT(B14/B10,"0%") -> 21%
A15: P2 - Medium | B15: =COUNTIF('Test Cases'!N5:N41,"P2 - Medium") -> 18 | C15: =TEXT(B15/B10,"0%") -> 55%
A16: P3 - Low | B16: =COUNTIF('Test Cases'!N5:N41,"P3 - Low") -> 8 | C16: =TEXT(B16/B10,"0%") -> 24%
A18: Suite Composition
A19: Metric | B19: Value
A20: Total test cases | B20: =COUNTIF('Test Cases'!A5:A41,"TC-*") -> 33
A21: Automated test cases | B21: =COUNTIF('Test Cases'!A5:A41,"TC-*") -> 33
A22: Smoke-tagged test cases | B22: =COUNTIF('Test Cases'!B5:B41,"Y") -> 4
A23: End-to-end test cases | B23: =COUNTIF('Test Cases'!D5:D41,"Y") -> 9
A24: Regression test cases | B24: =COUNTIF('Test Cases'!A5:A41,"TC-*") -> 33
A25: BDD feature files | B25: 6
A26: Page Object classes | B26: 5
A27: Latest run date | B27: 24-May-2026
A28: Latest run result | B28: PASS - 33 / 33 checks passed

Sheet Automation Mapping
A1: Automation Mapping - BDD Scenario <-> Test Case
A2: Every test case is automated. Each row maps a documented test case to its Gherkin scenario.
A3: TC ID | B3: Test Type | C3: Feature File | D3: BDD Scenario | E3: Gherkin Tags | F3: Automated
A4: TC-001 | B4: Functional | C4: account-registration.feature | D4: Register a new customer with valid details | E4: @registration @smoke @positive | F4: Yes
A5: TC-002 | B5: Functional | C5: account-registration.feature | D5: Registration is rejected when mandatory fields are empty | E5: @registration @negative | F5: Yes
A6: TC-003 | B6: Functional | C6: account-registration.feature | D6: Registration is rejected for an already registered username | E6: @registration @negative | F6: Yes
A7: TC-004 | B7: Functional | C7: account-login.feature | D7: Sign in with a newly created account and view the balance | E7: @login @smoke @positive | F7: Yes
A8: TC-005 | B8: Functional | C8: account-login.feature | D8: Sign in is rejected with invalid credentials | E8: @login @negative | F8: Yes
A9: TC-006 | B9: Functional | C9: account-login.feature | D9: Log out ends the session and returns to the login page | E9: @login @positive | F9: Yes
A10: TC-007 | B10: Boundary | C10: boundary.feature | D10: Registration is rejected when the password confirmation does not match | E10: @boundary @negative | F10: Yes
A11: TC-008 | B11: Boundary | C11: boundary.feature | D11: Registration is rejected when only some mandatory fields are completed | E11: @boundary @negative | F11: Yes
A12: TC-009 | B12: Boundary | C12: boundary.feature | D12: Registration succeeds with boundary-value field data [minimum-length] | E12: @boundary @positive | F12: Yes
A13: TC-010 | B13: Boundary | C13: boundary.feature | D13: Registration succeeds with boundary-value field data [maximum-length] | E13: @boundary @positive | F13: Yes
A14: TC-011 | B14: Boundary | C14: boundary.feature | D14: Registration succeeds with boundary-value field data [special-characters] | E14: @boundary @positive | F14: Yes
... A36: TC-033 | B36: Performance | C36: performance.feature | D36: The Accounts Overview page loads within the performance budget | E36: @performance | F36: Yes

Sheet Dashboard
A1: Execution Dashboard - ParaBank Automation Suite
A3: Suite Snapshot
A4: Total Test Cases | B4: Automated | C4: Feature Files | D4: Test Types | E4: Smoke Tests | F4: E2E Tests
A5: =COUNTIF('Test Cases'!A5:A41,"TC-*") -> 33 | B5: =COUNTIF('Test Cases'!A5:A41,"TC-*") -> 33 | C5: 6 | D5: 5 | E5: =COUNTIF('Test Cases'!B5:B41,"Y") -> 4 | F5: =COUNTIF('Test Cases'!D5:D41,"Y") -> 9
A7: Test Cases by Type
A8: Test Type | B8: Count | C8: % of Suite | D8: Test Type | E8: Count | F8: % of Suite
A9: Functional | B9: =COUNTIF('Test Cases'!F5:F41,"Functional") -> 6 | C9: =TEXT(B9/COUNTIF('Test Cases'!A5:A41,"TC-*"),"0%") -> 18% | D9: Access Control | E9: =COUNTIF('Test Cases'!F5:F41,"Access Control") -> 5 | F9: =TEXT(E9/COUNTIF('Test Cases'!A5:A41,"TC-*"),"0%") -> 15%
A10: Boundary | B10: =COUNTIF('Test Cases'!F5:F41,"Boundary") -> 8 | C10: =TEXT(B10/COUNTIF('Test Cases'!A5:A41,"TC-*"),"0%") -> 24% | D10: Performance | E10: =COUNTIF('Test Cases'!F5:F41,"Performance") -> 5 | F10: =TEXT(E10/COUNTIF('Test Cases'!A5:A41,"TC-*"),"0%") -> 15%
A11: Security | B11: =COUNTIF('Test Cases'!F5:F41,"Security") -> 9 | C11: =TEXT(B11/COUNTIF('Test Cases'!A5:A41,"TC-*"),"0%") -> 27%
A13: Latest Execution - 24-May-2026
A14: Status | B14: Count | C14: Note
A15: Pass | B15: =COUNTIF('Test Cases'!O5:O41,"Pass") -> 32 | C15: Checks that passed cleanly in the automated run.
A16: Observation | B16: =COUNTIF('Test Cases'!O5:O41,"Observation") -> 1 | C16: TC-019 - confirmed XSS exposure; runs as an expected failure (@fail) so the suite stays green.
A17: Run result | B17: PASS - 33 / 33 checks passed in 141 s. The automated runner reports all 33 scenarios as passed.

Sheet Guidelines
A1: Documentation Guidelines & Conventions
A2: Workbook Sheets
A3: Test Cases | B3: The full catalogue of 33 test cases, grouped by test type under blue section headers.
A4: Summary Report | B4: Coverage roll-ups by test type and priority. Counts auto-calculate from the Test Cases sheet.
A5: Automation Mapping | B5: Maps every test case to its BDD feature file, Gherkin scenario and tags.
A6: Dashboard | B6: KPI snapshot of the suite. All counts auto-calculate - no manual editing needed.
A7: Guidelines | B7: This sheet - conventions used throughout the workbook.
A8: Column Conventions
A9: Smoke / Reg. / E2E | B9: Y = the test case belongs to that suite; - = it does not.
A10: Auto | B10: Y = the test case is automated. Every case in this suite is automated.
A11: Test Type | B11: Functional, Boundary, Security, Access Control or Performance.
A12: Priority | B12: P1 - High (critical path), P2 - Medium, P3 - Low (edge / non-blocking).
A13: Status | B13: Pass, Fail, Not Run, Observation or Blocked. New suites start as 'Not Run'.
A14: Remarks | B14: Notes for Fail / Observation cases, or any other relevant context.
A15: Status Colours
A16: Green | B16: Pass
A17: Red | B17: Fail
A18: Yellow | B18: Not Run
A19: Blue | B19: Observation
A20: Purple | B20: Blocked
A21: Test Type Definitions
A22: Functional | B22: Verifies the core sign-up and login behaviour works as intended.
A23: Boundary | B23: Boundary-value analysis and input validation - min/max length, special characters, missing fields.
A24: Security | B24: Input masking, SQL/HTML injection resistance, HTTPS, session-cookie hardening, enumeration and brute-force resilience.
A25: Access Control | B25: Session management - protected pages must require an authenticated session.
A26: Performance | B26: Page-load and action response times measured against soft budgets (the demo uses a slow JPA backend).
A27: Running the Suite
A28: Command | B28: npm test - generates the BDD specs and runs all 33 scenarios.
A29: Report | B29: npm run report - opens the Playwright HTML report with screenshots.
A30: Tagged runs | B30: npm run test:smoke / test:registration / test:login, or 'playwright test --grep @security'.
A31: Known Defects
A32: TC-019 (XSS) | B32: ParaBank renders the registration first name unescaped - a stored XSS / HTML-injection exposure. The scenario asserts the secure behaviour and is tagged @fail (expected failure) so the suite stays green while flagging the defect.
